Workbook

Sheet Assumptions
A1: Assumptions
F2: Proj. | G2: Proj. | H2: Proj. | I2: Proj. | J2: Proj. | K2: Proj. | L2: Proj. | M2: Proj. | N2: Proj. | O2: Proj. | P2: Proj. | Q2: Proj. | R2: Proj. | S2: Proj. | T2: Proj. | U2: Proj. | V2: Proj. | W2: Proj. | X2: Proj.
F3: Q2 2018 | G3: Q3 2018 | H3: Q4 2018 | I3: Q1 2019 | J3: Q2 2019 | K3: Q3 2019 | L3: Q4 2019 | M3: Q1 2020 | N3: Q2 2020 | O3: Q3 2020 | P3: Q4 2020 | Q3: Q1 2021 | R3: Q2 2021 | S3: Q3 2021 | T3: Q4 2021 | U3: Q1 2022 | V3: Q2 2022 | W3: Q3 2022 | X3: Q4 2022
B4: Manufacturing Business Unit
C5: Units sold | F5: 9204 | G5: 8142 | H5: 10237.5 | I5: 8642 | J5: 10584.6 | K5: 9281.88 | L5: 11568.375 | M5: 9679.04 | N5: 11748.906 | O5: 10210.068 | P5: 12609.529 | Q5: 10453.363 | R5: 12571.329 | S5: 10822.672 | T5: 13240.005 | U5: 10871.498 | V5: 12948.469 | W5: 11039.126 | X5: 13372.405
C6: Sale price (per unit) | F6: 75 | G6: 75 | H6: 75 | I6: 77.5 | J6: 77.5 | K6: 77.5 | L6: 77.5 | M6: 77.5 | N6: 77.5 | O6: 77.5 | P6: 77.5 | Q6: 79 | R6: 79 | S6: 79 | T6: 79 | U6: 79 | V6: 79 | W6: 79 | X6: 79
C8: Cost of Goods
D9: Variable cost (per unit) | F9: 17.35 | G9: 17.35 | H9: 17.35 | I9: 17 | J9: 17 | K9: 17 | L9: 17 | M9: 16.85 | N9: 16.85 | O9: 16.85 | P9: 16.85 | Q9: 16.5 | R9: 16.5 | S9: 16.5 | T9: 16.5 | U9: 16.5 | V9: 16.5 | W9: 16.5 | X9: 16.5
C11: SG&A
D12: Fixed costs | F12: 12000 | G12: 12000 | H12: 12000 | I12: 12200 | J12: 12200 | K12: 12200 | L12: 12200 | M12: 12500 | N12: 12500 | O12: 12500 | P12: 12500 | Q12: 13000 | R12: 13000 | S12: 13000 | T12: 13000 | U12: 13000 | V12: 13000 | W12: 13000 | X12: 13000
D13: Variable cost (% of revenue) | F13: 0.125 | G13: 0.125 | H13: 0.125 | I13: 0.125 | J13: 0.125 | K13: 0.125 | L13: 0.125 | M13: 0.125 | N13: 0.125 | O13: 0.125 | P13: 0.125 | Q13: 0.125 | R13: 0.125 | S13: 0.125 | T13: 0.125 | U13: 0.125 | V13: 0.125 | W13: 0.125 | X13: 0.125
C15: Machinery, net
D16: Number of new machines | F16: 0 | G16: 0 | H16: 2 | I16: 0 | J16: 0 | K16: 0 | L16: 2 | M16: 0 | N16: 0 | O16: 0 | P16: 1 | Q16: 0 | R16: 0 | S16: 0 | T16: 1 | U16: 0 | W16: 0 | X16: 1
D17: Price per new macine | F17: 52000 | G17: 52000 | H17: 52000 | I17: 52000 | J17: 52000 | K17: 52000 | L17: 52000 | M17: 52000 | N17: 52000 | O17: 52000 | P17: 52000 | Q17: 52000 | R17: 52000 | S17: 52000 | T17: 52000 | U17: 52000 | V17: 52000 | W17: 52000 | X17: 52000
D18: Depreciation (% of quarterly lagged net machinery) | F18: =14%/4 -> 0.035 | G18: =14%/4 -> 0.035 | H18: =14%/4 -> 0.035 | I18: =14%/4 -> 0.035 | J18: =14%/4 -> 0.035 | K18: =14%/4 -> 0.035 | L18: =14%/4 -> 0.035 | M18: =14%/4 -> 0.035 | ... X18: =14%/4 -> 0.035
C20: Other Required PP&E, net | F20: 4000000 | G20: 4000000 | H20: 4000000 | I20: 4000000 | J20: 4300000 | K20: 4300000 | L20: 4300000 | M20: 4300000 | N20: 4600000 | O20: 4600000 | P20: 4600000 | Q20: 4600000 | R20: 5000000 | S20: 5000000 | T20: 5000000 | U20: 5000000 | V20: 5500000 | W20: 5500000 | X20: 5500000
D21: Depreciation (% of quarterly lagged Other PP&E, net) | F21: =1/15/4 -> 0.016666667 | G21: =1/15/4 -> 0.016666667 | H21: =1/15/4 -> 0.016666667 | I21: =1/15/4 -> 0.016666667 | J21: =1/15/4 -> 0.016666667 | K21: =1/15/4 -> 0.016666667 | L21: =1/15/4 -> 0.016666667 | M21: =1/15/4 -> 0.016666667 | ... X21: =1/15/4 -> 0.016666667
C23: Working capital
D24: Required cash (% revenue) | F24: 0.09 | G24: 0.09 | H24: 0.09 | I24: 0.09 | J24: 0.09 | K24: 0.09 | L24: 0.09 | M24: 0.09 | N24: 0.09 | O24: 0.09 | P24: 0.09 | Q24: 0.09 | R24: 0.09 | S24: 0.09 | T24: 0.09 | U24: 0.09 | V24: 0.09 | W24: 0.09 | X24: 0.09
D25: Days sales in inventory | F25: 74 | G25: 74 | H25: 74 | I25: 74 | J25: 73 | K25: 73 | L25: 73 | M25: 73 | N25: 73 | O25: 73 | P25: 73 | Q25: 72 | R25: 72 | S25: 72 | T25: 72 | U25: 72 | V25: 72 | W25: 72 | X25: 72
D26: Days sales in receivables | F26: 32 | G26: 32 | H26: 32 | I26: 32 | J26: 32 | K26: 32 | L26: 32 | M26: 32 | N26: 32 | O26: 32 | P26: 32 | Q26: 32 | R26: 32 | S26: 32 | T26: 32 | U26: 32 | V26: 32 | W26: 32 | X26: 32
D27: Days payables outstanding | F27: 10 | G27: 10 | H27: 10 | I27: 11 | J27: 11 | K27: 12 | L27: 12 | M27: 13 | N27: 13 | O27: 14 | P27: 14 | Q27: 15 | R27: 15 | S27: 15 | T27: 15 | U27: 15 | V27: 15 | W27: 15 | X27: 15
B29: Service Business Unit
C30: Quarterly ARPU (average revenue per *beginning* customer) | F30: 125 | G30: 125 | H30: 125 | I30: 131 | J30: 131 | K30: 131 | L30: 131 | M30: 134 | N30: 134 | O30: 134 | P30: 134 | Q30: 134 | R30: 134 | S30: 134 | T30: 134 | U30: 134 | V30: 134 | W30: 134 | X30: 134
C31: Customer assumptions
D32: Customer acquisition expense per new customer | F32: 225 | G32: 215 | H32: 205 | I32: 195 | J32: 190 | K32: 185 | L32: 180 | M32: 170 | N32: 170 | O32: 170 | P32: 170 | Q32: 160 | R32: 160 | S32: 160 | T32: 160 | U32: 150 | V32: 150 | W32: 150 | X32: 150
D33: Customer churn (% of beginning customers who quit service) | F33: 0.12 | G33: 0.12 | H33: 0.12 | I33: 0.11 | J33: 0.11 | K33: 0.11 | L33: 0.11 | M33: 0.1 | N33: 0.1 | O33: 0.1 | P33: 0.1 | Q33: 0.09 | R33: 0.09 | S33: 0.09 | T33: 0.09 | U33: 0.085 | V33: 0.085 | W33: 0.085 | X33: 0.085
C35: Cost of Goods per customer (use beginning customers) | F35: 70 | G35: 70 | H35: 70 | I35: 72 | J35: 72 | K35: 72 | L35: 72 | M35: 74 | N35: 74 | O35: 74 | P35: 74 | Q35: 76 | R35: 76 | S35: 76 | T35: 76 | U35: 76 | V35: 76 | W35: 76 | X35: 76
C37: SG&A
D38: Planned customer acquisiion expense | F38: 300000 | G38: 318000 | H38: 318000 | I38: 316500 | J38: 316500 | K38: 335490 | L38: 335490 | M38: 332325 | N38: 332325 | O38: 352264.5 | P38: 352264.5 | Q38: 347279.62 | R38: 347279.62 | S38: 368116.4 | T38: 368116.4 | U38: 361170.81 | V38: 361170.81 | W38: 382841.06 | X38: 382841.06
D39: Other expenses | F39: 10000 | G39: 12000 | H39: 12000 | I39: 12000 | J39: 12000 | K39: 12000 | L39: 12000 | M39: 15000 | N39: 15000 | O39: 15000 | P39: 15000 | Q39: 20000 | R39: 20000 | S39: 20000 | T39: 20000 | U39: 25000 | V39: 25000 | W39: 25000 | X39: 25000
C41: Capital expenditures
D42: "Success based" (capex per new customer) | F42: 67 | G42: 67 | H42: 67 | I42: 69 | J42: 69 | K42: 69 | L42: 69 | M42: 71 | N42: 71 | O42: 71 | P42: 71 | Q42: 75 | R42: 75 | S42: 75 | T42: 75 | U42: 75 | V42: 75 | W42: 75 | X42: 75
D43: "Maintenance" (% of depreciation) | F43: 0.8 | G43: 0.8 | H43: 0.8 | I43: 0.8 | J43: 0.8 | K43: 0.8 | L43: 0.8 | M43: 0.8 | N43: 0.8 | O43: 0.8 | P43: 0.8 | Q43: 0.8 | R43: 0.8 | S43: 0.8 | T43: 0.8 | U43: 0.8 | V43: 0.8 | W43: 0.8 | X43: 0.8
C45: Depreciation (% of quarterly lagged net fixed assets) | F45: =8%/4 -> 0.02 | G45: =8%/4 -> 0.02 | H45: =8%/4 -> 0.02 | I45: =8%/4 -> 0.02 | J45: =8%/4 -> 0.02 | K45: =8%/4 -> 0.02 | L45: =8%/4 -> 0.02 | M45: =8%/4 -> 0.02 | ... X45: =8%/4 -> 0.02
C47: Working capital
D48: Required cash (% of total service unit's assets) | F48: 0.13 | G48: 0.13 | H48: 0.13 | I48: 0.13 | J48: 0.13 | K48: 0.13 | L48: 0.13 | M48: 0.13 | N48: 0.13 | O48: 0.13 | P48: 0.13 | Q48: 0.13 | R48: 0.13 | S48: 0.13 | T48: 0.13 | U48: 0.13 | V48: 0.13 | W48: 0.13 | X48: 0.13
D49: Days sales in inventory (assume no inventory) | F49: 0 | G49: 0 | H49: 0 | I49: 0 | J49: 0 | K49: 0 | L49: 0 | M49: 0 | N49: 0 | O49: 0 | P49: 0 | Q49: 0 | R49: 0 | S49: 0 | T49: 0 | U49: 0 | V49: 0 | W49: 0 | X49: 0
D50: Days sales in receivables | F50: 28 | G50: 28 | H50: 28 | I50: 28 | J50: 28 | K50: 28 | L50: 28 | M50: 28 | N50: 28 | O50: 28 | P50: 28 | Q50: 28 | R50: 28 | S50: 28 | T50: 28 | U50: 28 | V50: 28 | W50: 28 | X50: 28
D51: Days payables outstanding | F51: 18 | G51: 18 | H51: 17 | I51: 17 | J51: 17 | K51: 17 | L51: 17 | M51: 16 | N51: 16 | O51: 16 | P51: 16 | Q51: 15 | R51: 15 | S51: 15 | T51: 15 | U51: 15 | V51: 15 | W51: 15 | X51: 15
...

Sheet COMPS
A1: Comparable Firm Analysis
D3: Share | E3: # shrs | F3: Book Value | G3: TTM | H3: Observed | I3: Tax | K3: Debt to Equity | L3: Your Professional
D4: Price | E4: Outstanding | F4: Debt | G4: EBITDA | H4: Beta | I4: Rate | L4: Classification
B5: Manufacturing
C6: Business A | D6: 17.46 | E6: 8113783 | F6: 17000000 | G6: 32043263 | H6: 1.622 | I6: 0.375 | K6: =(F6/E6)*D6 -> 36.582196 | L6: "mature & moderate growth"
C7: Business B | D7: 53.91 | E7: 1138260 | F7: 13500000 | G7: 12645489 | H7: 1.551 | I7: 0.34 | K7: =(F7/E7)*D7 -> 639.3838 | L7: "mature & moderate growth"
C8: Business C | D8: 11.26 | E8: 9069952 | F8: 48000000 | G8: 39847189 | H8: 1.532 | I8: 0.38 | K8: =(F8/E8)*D8 -> 59.590172 | L8: "mature & moderate growth"
C9: Business D | D9: 27.01 | E9: 629396 | F9: 3400000 | G9: 1080564 | H9: 1.667 | I9: 0.365 | K9: =(F9/E9)*D9 -> 145.90814 | L9: "younger & quicker growth"
C10: Business E | D10: 104.98 | E10: 1734457 | F10: 65550000 | G10: 45164743 | H10: 1.365 | I10: 0.395 | K10: =(F10/E10)*D10 -> 3967.489 | L10: "mature & moderate growth"
C11: Business F | D11: 19.44 | E11: 1876523 | F11: 9484700 | G11: 2969480 | H11: 1.745 | I11: 0.362 | K11: =(F11/E11)*D11 -> 98.257558 | L11: "younger & quicker growth"
C12: Business G | D12: 29.55 | E12: 1687576 | F12: 4488110 | G12: 3300726 | H12: 1.612 | I12: 0.353 | K12: =(F12/E12)*D12 -> 78.588254 | L12: "younger & quicker growth"
B14: Service
C15: Business H | D15: 37.54 | E15: 1116379 | F15: 13410843 | G15: 4837001 | H15: 1.185 | I15: 0.385 | K15: =(F15/E15)*D15 -> 450.96069 | L15: "mature & moderate growth"
C16: Business I | D16: 12.12 | E16: 1943312 | F16: 2826353 | G16: 929967 | H16: 1.171 | I16: 0.379 | K16: =(F16/E16)*D16 -> 17.627328 | L16: "younger & quicker growth"
B19: 30-Year US Treasury Rate (29/3/2019) | I19: 0.0302
B20: Equity Market Risk Premium (Assumed) | I20: 0.0596
B21: Estimated Cost of Debt Capital | I21: 0.0625
B23: Cardinal's Target Debt / Equity Ratio | I23: =1/8 -> 0.125
C24: (you can assume that the D/E Ratio is the same for each business unit)

Sheet Manufacturing
A1: Manufacturing Details
C2: Actual | D2: Actual | E2: Actual | F2: Actual | G2: Projected | H2: Projected | I2: Projected | J2: Projected | K2: Projected | L2: Projected | M2: Projected | N2: Projected | O2: Projected | P2: Projected | Q2: Projected | R2: Projected | S2: Projected | T2: Projected | U2: Projected | V2: Projected | W2: Projected | X2: Projected | Y2: Projected
C3: Q2 2017 | D3: Q3 2017 | E3: Q4 2017 | F3: Q1 2018 | G3: Q2 2018 | H3: Q3 2018 | I3: Q4 2018 | J3: Q1 2019 | K3: Q2 2019 | L3: Q3 2019 | M3: Q4 2019 | N3: Q1 2020 | O3: Q2 2020 | P3: Q3 2020 | Q3: Q4 2020 | R3: Q1 2021 | S3: Q2 2021 | T3: Q3 2021 | U3: Q4 2021 | V3: Q1 2022 | W3: Q2 2022 | X3: Q3 2022 | Y3: Q4 2022
B4: Sales | C4: 585000 | D4: 517500 | E4: 656250 | F4: 558750 | G4: =Assumptions!F5*Assumptions!F6 -> 690300 | H4: =Assumptions!G5*Assumptions!G6 -> 610650 | I4: =Assumptions!H5*Assumptions!H6 -> 767812.5 | J4: =Assumptions!I5*Assumptions!I6 -> 669755 | K4: =Assumptions!J5*Assumptions!J6 -> 820306.5 | L4: =Assumptions!K5*Assumptions!K6 -> 719345.7 | M4: =Assumptions!L5*Assumptions!L6 -> 896549.06 | N4: =Assumptions!M5*Assumptions!M6 -> 750125.6 | ... Y4: =Assumptions!X5*Assumptions!X6 -> 1056420
B5: Cost of Goods | C5: -135330 | D5: -119715 | E5: -151812.5 | F5: -129257.5 | G5: =-Assumptions!F5*Assumptions!F9 -> -159689.4 | H5: =-Assumptions!G5*Assumptions!G9 -> -141263.7 | I5: =-Assumptions!H5*Assumptions!H9 -> -177620.62 | J5: =-Assumptions!I5*Assumptions!I9 -> -146914 | K5: =-Assumptions!J5*Assumptions!J9 -> -179938.2 | L5: =-Assumptions!K5*Assumptions!K9 -> -157791.96 | M5: =-Assumptions!L5*Assumptions!L9 -> -196662.37 | N5: =-Assumptions!M5*Assumptions!M9 -> -163091.82 | ... Y5: =-Assumptions!X5*Assumptions!X9 -> -220644.69
B6: Gross Margin | C6: 449670 | D6: 397785 | E6: 504437.5 | F6: 429492.5 | G6: =SUM(G4:G5) -> 530610.6 | H6: =SUM(H4:H5) -> 469386.3 | I6: =SUM(I4:I5) -> 590191.88 | J6: =SUM(J4:J5) -> 522841 | K6: =SUM(K4:K5) -> 640368.3 | L6: =SUM(L4:L5) -> 561553.74 | M6: =SUM(M4:M5) -> 699886.69 | N6: =SUM(N4:N5) -> 587033.78 | ... Y6: =SUM(Y4:Y5) -> 835775.33
B8: SG&A | C8: -84625 | D8: -76187.5 | E8: -93531.25 | F8: -81843.75 | G8: =(Assumptions!F12+((Assumptions!F5*Assumptions!F6)*Assumptions!F13))*-1 -> -98287.5 | H8: =(Assumptions!G12+((Assumptions!G5*Assumptions!G6)*Assumptions!G13))*-1 -> -88331.25 | I8: =(Assumptions!H12+((Assumptions!H5*Assumptions!H6)*Assumptions!H13))*-1 -> -107976.56 | J8: =(Assumptions!I12+((Assumptions!I5*Assumptions!I6)*Assumptions!I13))*-1 -> -95919.375 | K8: =(Assumptions!J12+((Assumptions!J5*Assumptions!J6)*Assumptions!J13))*-1 -> -114738.31 | L8: =(Assumptions!K12+((Assumptions!K5*Assumptions!K6)*Assumptions!K13))*-1 -> -102118.21 | M8: =(Assumptions!L12+((Assumptions!L5*Assumptions!L6)*Assumptions!L13))*-1 -> -124268.63 | N8: =(Assumptions!M12+((Assumptions!M5*Assumptions!M6)*Assumptions!M13))*-1 -> -106265.7 | ... Y8: =(Assumptions!X12+((Assumptions!X5*Assumptions!X6)*Assumptions!X13))*-1 -> -145052.5
B9: Depreciation (Machines) | C9: -7280 | D9: -7025.2 | E9: -6779.318 | F9: -6542.0419 | G9: =-F13*Assumptions!F18 -> -6313.0704 | H9: =-G13*Assumptions!G18 -> -6092.1129 | I9: =-H13*Assumptions!H18 -> -5878.889 | J9: =-I13*Assumptions!I18 -> -9313.1279 | K9: =-J13*Assumptions!J18 -> -8987.1684 | L9: =-K13*Assumptions!K18 -> -8672.6175 | M9: =-L13*Assumptions!L18 -> -8369.0759 | N9: =-M13*Assumptions!M18 -> -11716.158 | ... Y9: =-X13*Assumptions!X18 -> -10971.249
B10: Depreciation (Other) | C10: -65000 | D10: -65166.667 | E10: -65500 | F10: -65666.667 | G10: =-F14*Assumptions!F21 -> -66500 | H10: =-G14*Assumptions!G21 -> -66666.667 | I10: =-H14*Assumptions!H21 -> -66666.667 | J10: =-I14*Assumptions!I21 -> -66666.667 | K10: =-J14*Assumptions!J21 -> -66666.667 | L10: =-K14*Assumptions!K21 -> -71666.667 | M10: =-L14*Assumptions!L21 -> -71666.667 | N10: =-M14*Assumptions!M21 -> -71666.667 | ... Y10: =-X14*Assumptions!X21 -> -91666.667
B11: EBIT | C11: 292765 | D11: 249405.63 | E11: 338626.93 | F11: 275440.04 | G11: =G6+G8+G9+G10 -> 359510.03 | H11: =H6+H8+H9+H10 -> 308296.27 | I11: =I6+I8+I9+I10 -> 409669.76 | J11: =J6+J8+J9+J10 -> 350941.83 | K11: =K6+K8+K9+K10 -> 449976.15 | L11: =L6+L8+L9+L10 -> 379096.24 | M11: =M6+M8+M9+M10 -> 495582.31 | N11: =N6+N8+N9+N10 -> 397385.25 | ... Y11: =Y6+Y8+Y9+Y10 -> 588084.91
B13: Net PP&E (Machines) | C13: 200720 | D13: 193694.8 | E13: 186915.48 | F13: 180373.44 | G13: =(Assumptions!F16*Assumptions!F17)+F13+G9 -> 174060.37 | H13: =(Assumptions!G16*Assumptions!G17)+G13+H9 -> 167968.26 | I13: =(Assumptions!H16*Assumptions!H17)+H13+I9 -> 266089.37 | J13: =(Assumptions!I16*Assumptions!I17)+I13+J9 -> 256776.24 | K13: =(Assumptions!J16*Assumptions!J17)+J13+K9 -> 247789.07 | L13: =(Assumptions!K16*Assumptions!K17)+K13+L9 -> 239116.45 | M13: =(Assumptions!L16*Assumptions!L17)+L13+M9 -> 334747.38 | N13: =(Assumptions!M16*Assumptions!M17)+M13+N9 -> 323031.22 | ... Y13: =(Assumptions!X16*Assumptions!X17)+X13+Y9 -> 354493
B14: Net Other PP&E | C14: 3910000 | D14: 3930000 | E14: 3940000 | F14: 3990000 | G14: =Assumptions!F20 -> 4000000 | H14: =Assumptions!G20 -> 4000000 | I14: =Assumptions!H20 -> 4000000 | J14: =Assumptions!I20 -> 4000000 | K14: =Assumptions!J20 -> 4300000 | L14: =Assumptions!K20 -> 4300000 | M14: =Assumptions!L20 -> 4300000 | N14: =Assumptions!M20 -> 4300000 | ... Y14: =Assumptions!X20 -> 5500000
B15: Total Net PP&E | C15: 4110720 | D15: 4123694.8 | E15: 4126915.5 | F15: 4170373.4 | G15: =SUM(G13:G14) -> 4174060.4 | H15: =SUM(H13:H14) -> 4167968.3 | I15: =SUM(I13:I14) -> 4266089.4 | J15: =SUM(J13:J14) -> 4256776.2 | K15: =SUM(K13:K14) -> 4547789.1 | L15: =SUM(L13:L14) -> 4539116.5 | M15: =SUM(M13:M14) -> 4634747.4 | N15: =SUM(N13:N14) -> 4623031.2 | ... Y15: =SUM(Y13:Y14) -> 5854493
B17: Required Cash | C17: 52650 | D17: 46575 | E17: 59062.5 | F17: 50287.5 | G17: =Assumptions!F24*(Assumptions!F5*Assumptions!F6) -> 62127 | H17: =Assumptions!G24*(Assumptions!G5*Assumptions!G6) -> 54958.5 | I17: =Assumptions!H24*(Assumptions!H5*Assumptions!H6) -> 69103.125 | J17: =Assumptions!I24*(Assumptions!I5*Assumptions!I6) -> 60277.95 | K17: =Assumptions!J24*(Assumptions!J5*Assumptions!J6) -> 73827.585 | L17: =Assumptions!K24*(Assumptions!K5*Assumptions!K6) -> 64741.113 | M17: =Assumptions!L24*(Assumptions!L5*Assumptions!L6) -> 80689.416 | N17: =Assumptions!M24*(Assumptions!M5*Assumptions!M6) -> 67511.304 | ... Y17: =Assumptions!X24*(Assumptions!X5*Assumptions!X6) -> 95077.801
B18: Inventory | C18: 109747.07 | D18: 97083.945 | E18: 123113.7 | F18: 104822.52 | G18: =-(Assumptions!F25/(365/4))*Manufacturing!G5 -> 129501.54 | H18: =-(Assumptions!G25/(365/4))*Manufacturing!H5 -> 114559.06 | I18: =-(Assumptions!H25/(365/4))*Manufacturing!I5 -> 144043.03 | J18: =-(Assumptions!I25/(365/4))*Manufacturing!J5 -> 119141.22 | K18: =-(Assumptions!J25/(365/4))*Manufacturing!K5 -> 143950.56 | L18: =-(Assumptions!K25/(365/4))*Manufacturing!L5 -> 126233.57 | M18: =-(Assumptions!L25/(365/4))*Manufacturing!M5 -> 157329.9 | N18: =-(Assumptions!M25/(365/4))*Manufacturing!N5 -> 130473.46 | ... Y18: =-(Assumptions!X25/(365/4))*Manufacturing!Y5 -> 174097.73
B19: Accounts Receivable | C19: 205150.68 | D19: 181479.45 | E19: 230136.99 | F19: 195945.21 | G19: =(Assumptions!F26/(365/4))*Manufacturing!G4 -> 242077.81 | H19: =(Assumptions!G26/(365/4))*Manufacturing!H4 -> 214145.75 | I19: =(Assumptions!H26/(365/4))*Manufacturing!I4 -> 269260.27 | J19: =(Assumptions!I26/(365/4))*Manufacturing!J4 -> 234872.99 | K19: =(Assumptions!J26/(365/4))*Manufacturing!K4 -> 287669.13 | L19: =(Assumptions!K26/(365/4))*Manufacturing!L4 -> 252263.7 | M19: =(Assumptions!L26/(365/4))*Manufacturing!M4 -> 314406.25 | N19: =(Assumptions!M26/(365/4))*Manufacturing!N4 -> 263057.74 | ... Y19: =(Assumptions!X26/(365/4))*Manufacturing!Y4 -> 370470.58
B20: Accounts Payable | C20: 37076.712 | D20: 32798.63 | E20: 41592.466 | F20: 35413.014 | G20: =-(Assumptions!F27/(365/4))*Manufacturing!G5 -> 17500.208 | H20: =-(Assumptions!G27/(365/4))*Manufacturing!H5 -> 15480.953 | I20: =-(Assumptions!H27/(365/4))*Manufacturing!I5 -> 19465.274 | J20: =-(Assumptions!I27/(365/4))*Manufacturing!J5 -> 17710.181 | K20: =-(Assumptions!J27/(365/4))*Manufacturing!K5 -> 21691.18 | L20: =-(Assumptions!K27/(365/4))*Manufacturing!L5 -> 20750.724 | M20: =-(Assumptions!L27/(365/4))*Manufacturing!M5 -> 25862.449 | N20: =-(Assumptions!M27/(365/4))*Manufacturing!N5 -> 23235 | ... Y20: =-(Assumptions!X27/(365/4))*Manufacturing!Y5 -> 36270.359

Sheet Service
A1: Service Details
C2: Actual | D2: Actual | E2: Actual | F2: Actual | G2: Projected | H2: Projected | I2: Projected | J2: Projected | K2: Projected | L2: Projected | M2: Projected | N2: Projected | O2: Projected | P2: Projected | Q2: Projected | R2: Projected | S2: Projected | T2: Projected | U2: Projected | V2: Projected | W2: Projected | X2: Projected | Y2: Projected
C3: Q2 2017 | D3: Q3 2017 | E3: Q4 2017 | F3: Q1 2018 | G3: Q2 2018 | H3: Q3 2018 | I3: Q4 2018 | J3: Q1 2019 | K3: Q2 2019 | L3: Q3 2019 | M3: Q4 2019 | N3: Q1 2020 | O3: Q2 2020 | P3: Q3 2020 | Q3: Q4 2020 | R3: Q1 2021 | S3: Q2 2021 | T3: Q3 2021 | U3: Q4 2021 | V3: Q1 2022 | W3: Q2 2022 | X3: Q3 2022 | Y3: Q4 2022
B4: Sales | C4: 543000 | D4: 602840 | E4: 680499.2 | F4: 748839.3 | G4: =(Assumptions!F30*Service!F23) -> 825645.25 | H4: =(Assumptions!G30*Service!G23) -> 893234.48 | I4: =(Assumptions!H30*Service!H23) -> 970930.07 | J4: =(Assumptions!I30*Service!I23) -> 1098640.3 | K4: =(Assumptions!J30*Service!J23) -> 1190412.9 | L4: =(Assumptions!K30*Service!K23) -> 1277685.9 | M4: =(Assumptions!L30*Service!L23) -> 1374703.7 | N4: =(Assumptions!M30*Service!M23) -> 1501258.7 | ... Y4: =(Assumptions!X30*Service!X23) -> 2717211.9
B5: Cost of Goods | C5: -295392 | D5: -327944.96 | E5: -370191.56 | F5: -419350.01 | G5: =-F23*Assumptions!F35 -> -462361.34 | H5: =-G23*Assumptions!G35 -> -500211.31 | I5: =-H23*Assumptions!H35 -> -543720.84 | J5: =-I23*Assumptions!I35 -> -603832.84 | K5: =-J23*Assumptions!J35 -> -654272.76 | L5: =-K23*Assumptions!K35 -> -702239.6 | M5: =-L23*Assumptions!L35 -> -755562.33 | N5: =-M23*Assumptions!M35 -> -829053.32 | ... Y5: =-X23*Assumptions!X35 -> -1541105.2
B6: Gross Margin | C6: 247608 | D6: 274895.04 | E6: 310307.64 | F6: 329489.29 | G6: =SUM(G4:G5) -> 363283.91 | H6: =SUM(H4:H5) -> 393023.17 | I6: =SUM(I4:I5) -> 427209.23 | J6: =SUM(J4:J5) -> 494807.46 | K6: =SUM(K4:K5) -> 536140.18 | L6: =SUM(L4:L5) -> 575446.34 | M6: =SUM(M4:M5) -> 619141.35 | N6: =SUM(N4:N5) -> 672205.39 | ... Y6: =SUM(Y4:Y5) -> 1176106.6
B8: SG&A | C8: -310000 | D8: -310000 | E8: -310000 | F8: -310000 | G8: =-SUM(Assumptions!F38:F39) -> -310000 | H8: =-SUM(Assumptions!G38:G39) -> -330000 | I8: =-SUM(Assumptions!H38:H39) -> -330000 | J8: =-SUM(Assumptions!I38:I39) -> -328500 | K8: =-SUM(Assumptions!J38:J39) -> -328500 | L8: =-SUM(Assumptions!K38:K39) -> -347490 | M8: =-SUM(Assumptions!L38:L39) -> -347490 | N8: =-SUM(Assumptions!M38:M39) -> -347325 | ... Y8: =-SUM(Assumptions!X38:X39) -> -407841.06
B9: Depreciation | C9: -70000 | D9: -71020 | E9: -72295.92 | F9: -73566.736 | G9: =-F12*(Assumptions!F45) -> -75059.136 | H9: =-G12*(Assumptions!G45) -> -76545.566 | I9: =-H12*(Assumptions!H45) -> -78221.337 | J9: =-I12*(Assumptions!I45) -> -79987.086 | K9: =-J12*(Assumptions!J45) -> -81906.984 | L9: =-K12*(Assumptions!K45) -> -83878.146 | M9: =-L12*(Assumptions!L45) -> -86045.207 | N9: =-M12*(Assumptions!M45) -> -88273.116 | ... Y9: =-X12*(Assumptions!X45) -> -119704.99
B10: EBIT | C10: -132392 | D10: -106124.96 | E10: -71988.285 | F10: -54077.446 | G10: =SUM(G6+G8+G9) -> -21775.227 | H10: =SUM(H6+H8+H9) -> -13522.393 | I10: =SUM(I6+I8+I9) -> 18987.892 | J10: =SUM(J6+J8+J9) -> 86320.378 | K10: =SUM(K6+K8+K9) -> 125733.2 | L10: =SUM(L6+L8+L9) -> 144078.19 | M10: =SUM(M6+M8+M9) -> 185606.14 | N10: =SUM(N6+N8+N9) -> 236607.28 | ... Y10: =SUM(Y6+Y8+Y9) -> 648560.58
B12: Net PP&E | C12: 3551000 | D12: 3614796 | E12: 3678336.8 | F12: 3752956.8 | G12: =F12+G21*Assumptions!F42+Assumptions!F43*-Service!G9+Service!G9 -> 3827278.3 | H12: =G12+H21*Assumptions!G42+Assumptions!G43*-Service!H9+Service!H9 -> 3911066.9 | I12: =H12+I21*Assumptions!H42+Assumptions!H43*-Service!I9+Service!I9 -> 3999354.3 | J12: =I12+J21*Assumptions!I42+Assumptions!I43*-Service!J9+Service!J9 -> 4095349.2 | K12: =J12+K21*Assumptions!J42+Assumptions!J43*-Service!K9+Service!K9 -> 4193907.3 | L12: =K12+L21*Assumptions!K42+Assumptions!K43*-Service!L9+Service!L9 -> 4302260.4 | M12: =L12+M21*Assumptions!L42+Assumptions!L43*-Service!M9+Service!M9 -> 4413655.8 | N12: =M12+N21*Assumptions!M42+Assumptions!M43*-Service!N9+Service!N9 -> 4534795.7 | ... Y12: =X12+Y21*Assumptions!X42+Assumptions!X43*-Service!Y9+Service!Y9 -> 6152729.1
B14: Required Cash | C14: 555506.31 | D14: 567782.78 | E14: 580838.14 | F14: 595121.71 | G14: =(Assumptions!F48*(Service!G15+Service!G16+Service!G12))/(1-Assumptions!F48) -> 609748.86 | H14: =(Assumptions!G48*(Service!H15+Service!H16+Service!H12))/(1-Assumptions!G48) -> 625368.03 | I14: =(Assumptions!H48*(Service!I15+Service!I16+Service!I12))/(1-Assumptions!H48) -> 642122.83 | J14: =(Assumptions!I48*(Service!J15+Service!J16+Service!J12))/(1-Assumptions!I48) -> 662322.54 | K14: =(Assumptions!J48*(Service!K15+Service!K16+Service!K12))/(1-Assumptions!J48) -> 681257.48 | L14: =(Assumptions!K48*(Service!L15+Service!L16+Service!L12))/(1-Assumptions!K48) -> 701449.73 | M14: =(Assumptions!L48*(Service!M15+Service!M16+Service!M12))/(1-Assumptions!L48) -> 722543.39 | N14: =(Assumptions!M48*(Service!N15+Service!N16+Service!N12))/(1-Assumptions!M48) -> 746447.44 | ... Y14: =(Assumptions!X48*(Service!Y15+Service!Y16+Service!Y12))/(1-Assumptions!X48) -> 1043960.3
B15: Inventory | C15: 0 | D15: 0 | E15: 0 | F15: 0 | G15: =Assumptions!F49 -> 0 | H15: =Assumptions!G49 -> 0 | I15: =Assumptions!H49 -> 0 | J15: =Assumptions!I49 -> 0 | K15: =Assumptions!J49 -> 0 | L15: =Assumptions!K49 -> 0 | M15: =Assumptions!L49 -> 0 | N15: =Assumptions!M49 -> 0 | ... Y15: =Assumptions!X49 -> 0
B16: Accounts Receivable | C16: 166619.18 | D16: 184981.04 | E16: 208810.71 | F16: 229780.83 | G16: =(Assumptions!F50/(365/4))*Service!G4 -> 253348.68 | H16: =(Assumptions!G50/(365/4))*Service!H4 -> 274088.39 | I16: =(Assumptions!H50/(365/4))*Service!I4 -> 297929.23 | J16: =(Assumptions!I50/(365/4))*Service!J4 -> 337117.02 | K16: =(Assumptions!J50/(365/4))*Service!K4 -> 365277.4 | L16: =(Assumptions!K50/(365/4))*Service!L4 -> 392057.06 | M16: =(Assumptions!L50/(365/4))*Service!M4 -> 421826.88 | N16: =(Assumptions!M50/(365/4))*Service!N4 -> 460660.21 | ... Y16: =(Assumptions!X50/(365/4))*Service!Y4 -> 833774.6
B17: Accounts Payable | C17: 48557.589 | D17: 53908.761 | E17: 60853.408 | F17: 68934.248 | G17: =(Assumptions!F51/(365/4))*-Service!G5 -> 91205.524 | H17: =(Assumptions!G51/(365/4))*-Service!H5 -> 98671.82 | I17: =(Assumptions!H51/(365/4))*-Service!I5 -> 101295.94 | J17: =(Assumptions!I51/(365/4))*-Service!J5 -> 112494.88 | K17: =(Assumptions!J51/(365/4))*-Service!K5 -> 121891.91 | L17: =(Assumptions!K51/(365/4))*-Service!L5 -> 130828.2 | M17: =(Assumptions!L51/(365/4))*-Service!M5 -> 140762.3 | N17: =(Assumptions!M51/(365/4))*-Service!N5 -> 145368.25 | ... Y17: =(Assumptions!X51/(365/4))*-Service!Y5 -> 253332.37
B19: Customer Build
B20: Beginning Customers | C20: 4344 | D20: 4822.72 | E20: 5443.9936 | F20: 5990.7144 | G20: =F23 -> 6605.162 | H20: =G23 -> 7145.8759 | I20: =H23 -> 7767.4405 | J20: =I23 -> 8386.5672 | K20: =J23 -> 9087.1217 | L20: =K23 -> 9753.3278 | M20: =L23 -> 10493.921 | N20: =M23 -> 11203.423 | ... Y20: =X23 -> 20277.701
B21: Gross Additions | C21: 1000 | D21: 1200 | E21: 1200 | F21: 1333.3333 | G21: =Assumptions!F38/Assumptions!F32 -> 1333.3333 | H21: =Assumptions!G38/Assumptions!G32 -> 1479.0698 | I21: =Assumptions!H38/Assumptions!H32 -> 1551.2195 | J21: =Assumptions!I38/Assumptions!I32 -> 1623.0769 | K21: =Assumptions!J38/Assumptions!J32 -> 1665.7895 | L21: =Assumptions!K38/Assumptions!K32 -> 1813.4595 | M21: =Assumptions!L38/Assumptions!L32 -> 1863.8333 | N21: =Assumptions!M38/Assumptions!M32 -> 1954.8529 | ... Y21: =Assumptions!X38/Assumptions!X32 -> 2552.2737
B22: Churn | C22: -521.28 | D22: -578.7264 | E22: -653.27923 | F22: -718.88572 | G22: =-G20*Assumptions!F33 -> -792.61944 | H22: =-H20*Assumptions!G33 -> -857.5051 | I22: =-I20*Assumptions!H33 -> -932.09286 | J22: =-J20*Assumptions!I33 -> -922.52239 | K22: =-K20*Assumptions!J33 -> -999.58339 | L22: =-L20*Assumptions!K33 -> -1072.8661 | M22: =-M20*Assumptions!L33 -> -1154.3313 | N22: =-N20*Assumptions!M33 -> -1120.3423 | ... Y22: =-Y20*Assumptions!X33 -> -1723.6045
B23: Ending Customers | C23: 4822.72 | D23: 5443.9936 | E23: 5990.7144 | F23: 6605.162 | G23: =SUM(G20:G22) -> 7145.8759 | H23: =SUM(H20:H22) -> 7767.4405 | I23: =SUM(I20:I22) -> 8386.5672 | J23: =SUM(J20:J22) -> 9087.1217 | K23: =SUM(K20:K22) -> 9753.3278 | L23: =SUM(L20:L22) -> 10493.921 | M23: =SUM(M20:M22) -> 11203.423 | N23: =SUM(N20:N22) -> 12037.934 | ... Y23: =SUM(Y20:Y22) -> 21106.37

Sheet Consolidated P&L
D2: Actual | E2: Actual | F2: Actual | G2: Actual | H2: Projected | I2: Projected | J2: Projected | K2: Projected | L2: Projected | M2: Projected | N2: Projected | O2: Projected | P2: Projected | Q2: Projected | R2: Projected | S2: Projected | T2: Projected | U2: Projected | V2: Projected | W2: Projected | X2: Projected | Y2: Projected | Z2: Projected
B3: Income Statement | D3: Q2 2017 | E3: Q3 2017 | F3: Q4 2017 | G3: Q1 2018 | H3: Q2 2018 | I3: Q3 2018 | J3: Q4 2018 | K3: Q1 2019 | L3: Q2 2019 | M3: Q3 2019 | N3: Q4 2019 | O3: Q1 2020 | P3: Q2 2020 | Q3: Q3 2020 | R3: Q4 2020 | S3: Q1 2021 | T3: Q2 2021 | U3: Q3 2021 | V3: Q4 2021 | W3: Q1 2022 | X3: Q2 2022 | Y3: Q3 2022 | Z3: Q4 2022
B4: Revenue | D4: 1128000 | E4: 1120340 | F4: 1336749.2 | G4: 1307589.3 | H4: =Manufacturing!G4+Service!G4 -> 1515945.2 | I4: =Manufacturing!H4+Service!H4 -> 1503884.5 | J4: =Manufacturing!I4+Service!I4 -> 1738742.6 | K4: =Manufacturing!J4+Service!J4 -> 1768395.3 | L4: =Manufacturing!K4+Service!K4 -> 2010719.4 | M4: =Manufacturing!L4+Service!L4 -> 1997031.6 | N4: =Manufacturing!M4+Service!M4 -> 2271252.7 | O4: =Manufacturing!N4+Service!N4 -> 2251384.3 | ... Z4: =Manufacturing!Y4+Service!Y4 -> 3773631.9
C5: Cost of Goods Sold | D5: -430722 | E5: -447659.96 | F5: -522004.06 | G5: -548607.51 | H5: =Manufacturing!G5+Service!G5 -> -622050.74 | I5: =Manufacturing!H5+Service!H5 -> -641475.01 | J5: =Manufacturing!I5+Service!I5 -> -721341.46 | K5: =Manufacturing!J5+Service!J5 -> -750746.84 | L5: =Manufacturing!K5+Service!K5 -> -834210.96 | M5: =Manufacturing!L5+Service!L5 -> -860031.56 | N5: =Manufacturing!M5+Service!M5 -> -952224.7 | O5: =Manufacturing!N5+Service!N5 -> -992145.14 | ... Z5: =Manufacturing!Y5+Service!Y5 -> -1761749.9
B6: Gross Profits | D6: 697278 | E6: 672680.04 | F6: 814745.14 | G6: 758981.79 | H6: =SUM(H4:H5) -> 893894.51 | I6: =SUM(I4:I5) -> 862409.47 | J6: =SUM(J4:J5) -> 1017401.1 | K6: =SUM(K4:K5) -> 1017648.5 | L6: =SUM(L4:L5) -> 1176508.5 | M6: =SUM(M4:M5) -> 1137000.1 | N6: =SUM(N4:N5) -> 1319028 | O6: =SUM(O4:O5) -> 1259239.2 | ... Z6: =SUM(Z4:Z5) -> 2011882
B8: Operating Expenses
C9: SG&A | D9: -394625 | E9: -386187.5 | F9: -403531.25 | G9: -391843.75 | H9: =Manufacturing!G8+Service!G8 -> -408287.5 | I9: =Manufacturing!H8+Service!H8 -> -418331.25 | J9: =Manufacturing!I8+Service!I8 -> -437976.56 | K9: =Manufacturing!J8+Service!J8 -> -424419.38 | L9: =Manufacturing!K8+Service!K8 -> -443238.31 | M9: =Manufacturing!L8+Service!L8 -> -449608.21 | N9: =Manufacturing!M8+Service!M8 -> -471758.63 | O9: =Manufacturing!N8+Service!N8 -> -453590.7 | ... Z9: =Manufacturing!Y8+Service!Y8 -> -552893.56
C10: Depreciation | D10: -142280 | E10: -143211.87 | F10: -144575.24 | G10: -145775.44 | H10: =Manufacturing!G9+Manufacturing!G10+Service!G9 -> -147872.21 | I10: =Manufacturing!H9+Manufacturing!H10+Service!H9 -> -149304.35 | J10: =Manufacturing!I9+Manufacturing!I10+Service!I9 -> -150766.89 | K10: =Manufacturing!J9+Manufacturing!J10+Service!J9 -> -155966.88 | L10: =Manufacturing!K9+Manufacturing!K10+Service!K9 -> -157560.82 | M10: =Manufacturing!L9+Manufacturing!L10+Service!L9 -> -164217.43 | N10: =Manufacturing!M9+Manufacturing!M10+Service!M9 -> -166080.95 | O10: =Manufacturing!N9+Manufacturing!N10+Service!N9 -> -171655.94 | ... Z10: =Manufacturing!Y9+Manufacturing!Y10+Service!Y9 -> -222342.91
B11: Total Opex | D11: -536905 | E11: -529399.37 | F11: -548106.49 | G11: -537619.19 | H11: =SUM(H9:H10) -> -556159.71 | I11: =SUM(I9:I10) -> -567635.6 | J11: =SUM(J9:J10) -> -588743.46 | K11: =SUM(K9:K10) -> -580386.26 | L11: =SUM(L9:L10) -> -600799.13 | M11: =SUM(M9:M10) -> -613825.64 | N11: =SUM(N9:N10) -> -637839.58 | O11: =SUM(O9:O10) -> -625246.64 | ... Z11: =SUM(Z9:Z10) -> -775236.47
B13: Interest Expense | D13: -38250 | E13: -53880.974 | F13: -53929.956 | G13: -54405.596 | H13: =-((Assumptions!F54/4)*'Consolidated BS'!F17)-(Assumptions!F55/4)*'Consolidated BS'!F21 -> -54040.619 | I13: =-((Assumptions!G54/4)*'Consolidated BS'!G17)-(Assumptions!G55/4)*'Consolidated BS'!G21 -> -54455.995 | J13: =-((Assumptions!H54/4)*'Consolidated BS'!H17)-(Assumptions!H55/4)*'Consolidated BS'!H21 -> -53208.325 | K13: =-((Assumptions!I54/4)*'Consolidated BS'!I17)-(Assumptions!I55/4)*'Consolidated BS'!I21 -> -54596.345 | L13: =-((Assumptions!J54/4)*'Consolidated BS'!J17)-(Assumptions!J55/4)*'Consolidated BS'!J21 -> -53125 | M13: =-((Assumptions!K54/4)*'Consolidated BS'!K17)-(Assumptions!K55/4)*'Consolidated BS'!K21 -> -55649.225 | N13: =-((Assumptions!L54/4)*'Consolidated BS'!L17)-(Assumptions!L55/4)*'Consolidated BS'!L21 -> -53125 | O13: =-((Assumptions!M54/4)*'Consolidated BS'!M17)-(Assumptions!M55/4)*'Consolidated BS'!M21 -> -53125 | ... Z13: =-((Assumptions!X54/4)*'Consolidated BS'!X17)-(Assumptions!X55/4)*'Consolidated BS'!X21 -> -98662.848
B15: Earnings before Tax | D15: 122123 | E15: 89399.7 | F15: 212708.69 | G15: 166957 | H15: =H6+H11+H13 -> 283694.18 | I15: =I6+I11+I13 -> 240317.88 | J15: =J6+J11+J13 -> 375449.32 | K15: =K6+K11+K13 -> 382665.86 | L15: =L6+L11+L13 -> 522584.35 | M15: =M6+M11+M13 -> 467525.21 | N15: =N6+N11+N13 -> 628063.46 | O15: =O6+O11+O13 -> 580867.53 | ... Z15: =Z6+Z11+Z13 -> 1137982.6
B17: Tax Expense | D17: -39079.36 | E17: -28607.904 | F17: -68066.781 | G17: -53426.24 | H17: =-H15*Assumptions!F62 -> -90782.139 | I17: =-I15*Assumptions!G62 -> -76901.722 | J17: =-J15*Assumptions!H62 -> -120143.78 | K17: =-K15*Assumptions!I62 -> -122453.08 | L17: =-L15*Assumptions!J62 -> -167226.99 | M17: =-M15*Assumptions!K62 -> -149608.07 | N17: =-N15*Assumptions!L62 -> -200980.31 | O17: =-O15*Assumptions!M62 -> -185877.61 | ... Z17: =-Z15*Assumptions!X62 -> -364154.45
B19: Net Income | D19: 83043.64 | E19: 60791.796 | F19: 144641.91 | G19: 113530.76 | H19: =H15+H17 -> 192912.04 | I19: =I15+I17 -> 163416.16 | J19: =J15+J17 -> 255305.54 | K19: =K15+K17 -> 260212.79 | L19: =L15+L17 -> 355357.36 | M19: =M15+M17 -> 317917.14 | N19: =N15+N17 -> 427083.15 | O19: =O15+O17 -> 394989.92 | ... Z19: =Z15+Z17 -> 773828.2

Sheet Consolidated BS
F2: Actual | G2: Projected | H2: Projected | I2: Projected | J2: Projected | K2: Projected | L2: Projected | M2: Projected | N2: Projected | O2: Projected | P2: Projected | Q2: Projected | R2: Projected | S2: Projected | T2: Projected | U2: Projected | V2: Projected | W2: Projected | X2: Projected | Y2: Projected
B3: Balance Sheet | F3: Q1 2018 | G3: Q2 2018 | H3: Q3 2018 | I3: Q4 2018 | J3: Q1 2019 | K3: Q2 2019 | L3: Q3 2019 | M3: Q4 2019 | N3: Q1 2020 | O3: Q2 2020 | P3: Q3 2020 | Q3: Q4 2020 | R3: Q1 2021 | S3: Q2 2021 | T3: Q3 2021 | U3: Q4 2021 | V3: Q1 2022 | W3: Q2 2022 | X3: Q3 2022 | Y3: Q4 2022
B4: Assets
C5: Current Assets
D6: Excess Cash | F6: 0 | G6: =MAX(G18+G21+G25+G26-G7-G8-G9-G12,0) -> 0 | H6: =MAX(H18+H21+H25+H26-H7-H8-H9-H12,0) -> 0 | I6: =MAX(I18+I21+I25+I26-I7-I8-I9-I12,0) -> 0 | J6: =MAX(J18+J21+J25+J26-J7-J8-J9-J12,0) -> 47535.548 | K6: =MAX(K18+K21+K25+K26-K7-K8-K9-K12,0) -> 0 | L6: =MAX(L18+L21+L25+L26-L7-L8-L9-L12,0) -> 29919.097 | M6: =MAX(M18+M21+M25+M26-M7-M8-M9-M12,0) -> 54971.014 | N6: =MAX(N18+N21+N25+N26-N7-N8-N9-N12,0) -> 171161.34 | ... Y6: =MAX(Y18+Y21+Y25+Y26-Y7-Y8-Y9-Y12,0) -> 0
D7: Required Cash | F7: 645409.21 | G7: =Manufacturing!G17+Service!G14 -> 671875.86 | H7: =Manufacturing!H17+Service!H14 -> 680326.53 | I7: =Manufacturing!I17+Service!I14 -> 711225.95 | J7: =Manufacturing!J17+Service!J14 -> 722600.49 | K7: =Manufacturing!K17+Service!K14 -> 755085.06 | L7: =Manufacturing!L17+Service!L14 -> 766190.84 | M7: =Manufacturing!M17+Service!M14 -> 803232.81 | N7: =Manufacturing!N17+Service!N14 -> 813958.74 | ... Y7: =Manufacturing!Y17+Service!Y14 -> 1139038.1
D8: Inventory | F8: 104822.52 | G8: =Manufacturing!G18+Service!G15 -> 129501.54 | H8: =Manufacturing!H18+Service!H15 -> 114559.06 | I8: =Manufacturing!I18+Service!I15 -> 144043.03 | J8: =Manufacturing!J18+Service!J15 -> 119141.22 | K8: =Manufacturing!K18+Service!K15 -> 143950.56 | L8: =Manufacturing!L18+Service!L15 -> 126233.57 | M8: =Manufacturing!M18+Service!M15 -> 157329.9 | N8: =Manufacturing!N18+Service!N15 -> 130473.46 | ... Y8: =Manufacturing!Y18+Service!Y15 -> 174097.73
D9: Accounts Receivable | F9: 425726.03 | G9: =Manufacturing!G19+Service!G16 -> 495426.49 | H9: =Manufacturing!H19+Service!H16 -> 488234.14 | I9: =Manufacturing!I19+Service!I16 -> 567189.5 | J9: =Manufacturing!J19+Service!J16 -> 571990.01 | K9: =Manufacturing!K19+Service!K16 -> 652946.53 | L9: =Manufacturing!L19+Service!L16 -> 644320.75 | M9: =Manufacturing!M19+Service!M16 -> 736233.13 | N9: =Manufacturing!N19+Service!N16 -> 723717.95 | ... Y9: =Manufacturing!Y19+Service!Y16 -> 1204245.2
C10: Total Current Assets | F10: 1175957.8 | G10: =SUM(G6:G9) -> 1296803.9 | H10: =SUM(H6:H9) -> 1283119.7 | I10: =SUM(I6:I9) -> 1422458.5 | J10: =SUM(J6:J9) -> 1461267.3 | K10: =SUM(K6:K9) -> 1551982.2 | L10: =SUM(L6:L9) -> 1566664.3 | M10: =SUM(M6:M9) -> 1751766.8 | N10: =SUM(N6:N9) -> 1839311.5 | ... Y10: =SUM(Y6:Y9) -> 2517381
C12: Equipment, net | F12: 7923330.2 | G12: =Service!G12+Manufacturing!G15 -> 8001338.7 | H12: =Service!H12+Manufacturing!H15 -> 8079035.1 | I12: =Service!I12+Manufacturing!I15 -> 8265443.7 | J12: =Service!J12+Manufacturing!J15 -> 8352125.4 | K12: =Service!K12+Manufacturing!K15 -> 8741696.3 | L12: =Service!L12+Manufacturing!L15 -> 8841376.8 | M12: =Service!M12+Manufacturing!M15 -> 9048403.2 | N12: =Service!N12+Manufacturing!N15 -> 9157827 | ... Y12: =Service!Y12+Manufacturing!Y15 -> 12007222
B13: Total Assets | F13: 9099288 | G13: =G10+G12 -> 9298142.6 | H13: =H10+H12 -> 9362154.9 | I13: =I10+I12 -> 9687902.2 | J13: =J10+J12 -> 9813392.7 | K13: =K10+K12 -> 10293678 | L13: =L10+L12 -> 10408041 | M13: =M10+M12 -> 10800170 | N13: =N10+N12 -> 10997138 | ... Y13: =Y10+Y12 -> 14524603
B15: Liabilities & Owners' Equity
C16: Current Liabilities
D17: Notes Payable | F17: 58599.641 | G17: =MAX(G7+G8+G9+G12-G18-G21-G25-G26,0) -> 85183.683 | H17: =MAX(H7+H8+H9+H12-H18-H21-H25-H26,0) -> 5332.7681 | I17: =MAX(I7+I8+I9+I12-I18-I21-I25-I26,0) -> 94166.095 | J17: =MAX(J7+J8+J9+J12-J18-J21-J25-J26,0) -> 0 | K17: =MAX(K7+K8+K9+K12-K18-K21-K25-K26,0) -> 161550.41 | L17: =MAX(L7+L8+L9+L12-L18-L21-L25-L26,0) -> 0 | M17: =MAX(M7+M8+M9+M12-M18-M21-M25-M26,0) -> 0 | N17: =MAX(N7+N8+N9+N12-N18-N21-N25-N26,0) -> 0 | ... Y17: =MAX(Y7+Y8+Y9+Y12-Y18-Y21-Y25-Y26,0) -> 69501.638
D18: Accounts Payable | F18: 104347.26 | G18: =Service!G17+Manufacturing!G20 -> 108705.73 | H18: =Service!H17+Manufacturing!H20 -> 114152.77 | I18: =Service!I17+Manufacturing!I20 -> 120761.21 | J18: =Service!J17+Manufacturing!J20 -> 130205.07 | K18: =Service!K17+Manufacturing!K20 -> 143583.09 | L18: =Service!L17+Manufacturing!L20 -> 151578.92 | M18: =Service!M17+Manufacturing!M20 -> 166624.75 | N18: =Service!N17+Manufacturing!N20 -> 168603.25 | ... Y18: =Service!Y17+Manufacturing!Y20 -> 289602.73
C19: Total Current Liabilities | F19: 162946.9 | G19: =SUM(G17:G18) -> 193889.42 | H19: =SUM(H17:H18) -> 119485.54 | I19: =SUM(I17:I18) -> 214927.31 | J19: =SUM(J17:J18) -> 130205.07 | K19: =SUM(K17:K18) -> 305133.5 | L19: =SUM(L17:L18) -> 151578.92 | M19: =SUM(M17:M18) -> 166624.75 | N19: =SUM(N17:N18) -> 168603.25 | ... Y19: =SUM(Y17:Y18) -> 359104.37
C21: Long Term Debt | F21: 2500000 | G21: =Assumptions!F58 -> 2500000 | H21: =Assumptions!G58 -> 2500000 | I21: =Assumptions!H58 -> 2500000 | J21: =Assumptions!I58 -> 2500000 | K21: =Assumptions!J58 -> 2500000 | L21: =Assumptions!K58 -> 2500000 | M21: =Assumptions!L58 -> 2500000 | N21: =Assumptions!M58 -> 2500000 | ... Y21: =Assumptions!X58 -> 6000000
B22: Total Liabilities | F22: 2662946.9 | G22: =G19+G21 -> 2693889.4 | H22: =H19+H21 -> 2619485.5 | I22: =I19+I21 -> 2714927.3 | J22: =J19+J21 -> 2630205.1 | K22: =K19+K21 -> 2805133.5 | L22: =L19+L21 -> 2651578.9 | M22: =M19+M21 -> 2666624.7 | N22: =N19+N21 -> 2668603.3 | ... Y22: =Y19+Y21 -> 6359104.4
C24: Common Stock
D25: Par and APIC | F25: 6200000 | G25: =Assumptions!F59 -> 6200000 | H25: =Assumptions!G59 -> 6200000 | I25: =Assumptions!H59 -> 6200000 | J25: =Assumptions!I59 -> 6200000 | K25: =Assumptions!J59 -> 6200000 | L25: =Assumptions!K59 -> 6200000 | M25: =Assumptions!L59 -> 6200000 | N25: =Assumptions!M59 -> 6200000 | ... Y25: =Assumptions!X59 -> 2680000
D26: Retained Earnings | F26: 236341.11 | G26: =F26+'Consolidated P&L'!H19-Assumptions!F60 -> 404253.15 | H26: =G26+'Consolidated P&L'!I19-Assumptions!G60 -> 542669.31 | I26: =H26+'Consolidated P&L'!J19-Assumptions!H60 -> 772974.85 | J26: =I26+'Consolidated P&L'!K19-Assumptions!I60 -> 983187.64 | K26: =J26+'Consolidated P&L'!L19-Assumptions!J60 -> 1288545 | L26: =K26+'Consolidated P&L'!M19-Assumptions!K60 -> 1556462.1 | M26: =L26+'Consolidated P&L'!N19-Assumptions!L60 -> 1933545.3 | N26: =M26+'Consolidated P&L'!O19-Assumptions!M60 -> 2128535.2 | ... Y26: =X26+'Consolidated P&L'!Z19-Assumptions!X60 -> 5485498.8
B27: Total Stockholders' Equity | F27: 6436341.1 | G27: =SUM(G25:G26) -> 6604253.2 | H27: =SUM(H25:H26) -> 6742669.3 | I27: =SUM(I25:I26) -> 6972974.9 | J27: =SUM(J25:J26) -> 7183187.6 | K27: =SUM(K25:K26) -> 7488545 | L27: =SUM(L25:L26) -> 7756462.1 | M27: =SUM(M25:M26) -> 8133545.3 | N27: =SUM(N25:N26) -> 8328535.2 | ... Y27: =SUM(Y25:Y26) -> 8165498.8
B29: Total Liabilities & Owners' Equity | F29: 9099288 | G29: =G22+G27 -> 9298142.6 | H29: =H22+H27 -> 9362154.9 | I29: =I22+I27 -> 9687902.2 | J29: =J22+J27 -> 9813392.7 | K29: =K22+K27 -> 10293678 | L29: =L22+L27 -> 10408041 | M29: =M22+M27 -> 10800170 | N29: =N22+N27 -> 10997138 | ... Y29: =Y22+Y27 -> 14524603
E31: nowc | F31: =F7+F8+F9-F18 -> 1071610.5 | G31: =G7+G8+G9-G18 -> 1188098.2 | H31: =H7+H8+H9-H18 -> 1168967 | I31: =I7+I8+I9-I18 -> 1301697.3 | J31: =J7+J8+J9-J18 -> 1283526.7 | K31: =K7+K8+K9-K18 -> 1408399.1 | L31: =L7+L8+L9-L18 -> 1385166.2 | M31: =M7+M8+M9-M18 -> 1530171.1 | ... Y31: =Y7+Y8+Y9-Y18 -> 2227778.3

Sheet Consolidated SCF
E2: Projected | F2: Projected | G2: Projected | H2: Projected | I2: Projected | J2: Projected | K2: Projected | L2: Projected | M2: Projected | N2: Projected | O2: Projected | P2: Projected | Q2: Projected | R2: Projected | S2: Projected | T2: Projected | U2: Projected | V2: Projected | W2: Projected
B3: Statement of Cash Flows | E3: Q2 2018 | F3: Q3 2018 | G3: Q4 2018 | H3: Q1 2019 | I3: Q2 2019 | J3: Q3 2019 | K3: Q4 2019 | L3: Q1 2020 | M3: Q2 2020 | N3: Q3 2020 | O3: Q4 2020 | P3: Q1 2021 | Q3: Q2 2021 | R3: Q3 2021 | S3: Q4 2021 | T3: Q1 2022 | U3: Q2 2022 | V3: Q3 2022 | W3: Q4 2022
C4: Cash Flow from Operating Activities
D5: Net income | E5: ='Consolidated P&L'!H19 -> 192912.04 | F5: ='Consolidated P&L'!I19 -> 163416.16 | G5: ='Consolidated P&L'!J19 -> 255305.54 | H5: ='Consolidated P&L'!K19 -> 260212.79 | I5: ='Consolidated P&L'!L19 -> 355357.36 | J5: ='Consolidated P&L'!M19 -> 317917.14 | K5: ='Consolidated P&L'!N19 -> 427083.15 | L5: ='Consolidated P&L'!O19 -> 394989.92 | ... W5: ='Consolidated P&L'!Z19 -> 773828.2
C6: Adjustments to Net Income
D7: Depreciation & Amortization | E7: ='Consolidated P&L'!H10*(-1) -> 147872.21 | F7: ='Consolidated P&L'!I10*(-1) -> 149304.35 | G7: ='Consolidated P&L'!J10*(-1) -> 150766.89 | H7: ='Consolidated P&L'!K10*(-1) -> 155966.88 | I7: ='Consolidated P&L'!L10*(-1) -> 157560.82 | J7: ='Consolidated P&L'!M10*(-1) -> 164217.43 | K7: ='Consolidated P&L'!N10*(-1) -> 166080.95 | L7: ='Consolidated P&L'!O10*(-1) -> 171655.94 | ... W7: ='Consolidated P&L'!Z10*(-1) -> 222342.91
D8: Accounts receivable | E8: =-('Consolidated BS'!G9-'Consolidated BS'!F9) -> -69700.456 | F8: =-('Consolidated BS'!H9-'Consolidated BS'!G9) -> 7192.3437 | G8: =-('Consolidated BS'!I9-'Consolidated BS'!H9) -> -78955.357 | H8: =-('Consolidated BS'!J9-'Consolidated BS'!I9) -> -4800.5102 | I8: =-('Consolidated BS'!K9-'Consolidated BS'!J9) -> -80956.515 | J8: =-('Consolidated BS'!L9-'Consolidated BS'!K9) -> 8625.7718 | K8: =-('Consolidated BS'!M9-'Consolidated BS'!L9) -> -91912.375 | L8: =-('Consolidated BS'!N9-'Consolidated BS'!M9) -> 12515.177 | ... W8: =-('Consolidated BS'!Y9-'Consolidated BS'!X9) -> -101879.75
D9: Inventory | E9: =-('Consolidated BS'!G8-'Consolidated BS'!F8) -> -24679.02 | F9: =-('Consolidated BS'!H8-'Consolidated BS'!G8) -> 14942.485 | G9: =-('Consolidated BS'!I8-'Consolidated BS'!H8) -> -29483.972 | H9: =-('Consolidated BS'!J8-'Consolidated BS'!I8) -> 24901.811 | I9: =-('Consolidated BS'!K8-'Consolidated BS'!J8) -> -24809.344 | J9: =-('Consolidated BS'!L8-'Consolidated BS'!K8) -> 17716.992 | K9: =-('Consolidated BS'!M8-'Consolidated BS'!L8) -> -31096.332 | L9: =-('Consolidated BS'!N8-'Consolidated BS'!M8) -> 26856.441 | ... W9: =-('Consolidated BS'!Y8-'Consolidated BS'!X8) -> -30377.384
D10: Accounts payable | E10: ='Consolidated BS'!G18-'Consolidated BS'!F18 -> 4358.4713 | F10: ='Consolidated BS'!H18-'Consolidated BS'!G18 -> 5447.0412 | G10: ='Consolidated BS'!I18-'Consolidated BS'!H18 -> 6608.4371 | H10: ='Consolidated BS'!J18-'Consolidated BS'!I18 -> 9443.8547 | I10: ='Consolidated BS'!K18-'Consolidated BS'!J18 -> 13378.027 | J10: ='Consolidated BS'!L18-'Consolidated BS'!K18 -> 7995.8309 | K10: ='Consolidated BS'!M18-'Consolidated BS'!L18 -> 15045.823 | L10: ='Consolidated BS'!N18-'Consolidated BS'!M18 -> 1978.5067 | ... W10: ='Consolidated BS'!Y18-'Consolidated BS'!X18 -> 17643.036
C11: Net Cash from Operating Activities | E11: =E5+E7+E8+E9+E10 -> 250763.25 | F11: =F5+F7+F8+F9+F10 -> 340302.38 | G11: =G5+G7+G8+G9+G10 -> 304241.54 | H11: =H5+H7+H8+H9+H10 -> 445724.82 | I11: =I5+I7+I8+I9+I10 -> 420530.34 | J11: =J5+J7+J8+J9+J10 -> 516473.17 | K11: =K5+K7+K8+K9+K10 -> 485201.22 | L11: =L5+L7+L8+L9+L10 -> 607995.98 | ... W11: =W5+W7+W8+W9+W10 -> 881557
C13: Cash Flow from Investing Activities
D14: Additions to equipment | E14: =-('Consolidated BS'!G12-'Consolidated BS'!F12)+'Consolidated P&L'!H10 -> -225880.64 | F14: =-('Consolidated BS'!H12-'Consolidated BS'!G12)+'Consolidated P&L'!I10 -> -227000.79 | G14: =-('Consolidated BS'!I12-'Consolidated BS'!H12)+'Consolidated P&L'!J10 -> -337175.44 | H14: =-('Consolidated BS'!J12-'Consolidated BS'!I12)+'Consolidated P&L'!K10 -> -242648.64 | I14: =-('Consolidated BS'!K12-'Consolidated BS'!J12)+'Consolidated P&L'!L10 -> -547131.73 | J14: =-('Consolidated BS'!L12-'Consolidated BS'!K12)+'Consolidated P&L'!M10 -> -263897.89 | K14: =-('Consolidated BS'!M12-'Consolidated BS'!L12)+'Consolidated P&L'!N10 -> -373107.33 | L14: =-('Consolidated BS'!N12-'Consolidated BS'!M12)+'Consolidated P&L'!O10 -> -281079.72 | ... W14: =-('Consolidated BS'!Y12-'Consolidated BS'!X12)+'Consolidated P&L'!Z10 -> -430851.19
C15: Net Cash from Investing Activities | E15: =E14 -> -225880.64 | F15: =F14 -> -227000.79 | G15: =G14 -> -337175.44 | H15: =H14 -> -242648.64 | I15: =I14 -> -547131.73 | J15: =J14 -> -263897.89 | K15: =K14 -> -373107.33 | L15: =L14 -> -281079.72 | ... W15: =W14 -> -430851.19
C17: Cash Flow from Financing Activities
D18: Proceeds from notes payable | E18: ='Consolidated BS'!G17-'Consolidated BS'!F17 -> 26584.042 | F18: ='Consolidated BS'!H17-'Consolidated BS'!G17 -> -79850.915 | G18: ='Consolidated BS'!I17-'Consolidated BS'!H17 -> 88833.327 | H18: ='Consolidated BS'!J17-'Consolidated BS'!I17 -> -94166.095 | I18: ='Consolidated BS'!K17-'Consolidated BS'!J17 -> 161550.41 | J18: ='Consolidated BS'!L17-'Consolidated BS'!K17 -> -161550.41 | K18: ='Consolidated BS'!M17-'Consolidated BS'!L17 -> 0 | L18: ='Consolidated BS'!N17-'Consolidated BS'!M17 -> 0 | ... W18: ='Consolidated BS'!Y17-'Consolidated BS'!X17 -> -23526.17
D19: Proceeds from Common stock | E19: ='Consolidated BS'!G25-'Consolidated BS'!F25 -> 0 | F19: ='Consolidated BS'!H25-'Consolidated BS'!G25 -> 0 | G19: ='Consolidated BS'!I25-'Consolidated BS'!H25 -> 0 | H19: ='Consolidated BS'!J25-'Consolidated BS'!I25 -> 0 | I19: ='Consolidated BS'!K25-'Consolidated BS'!J25 -> 0 | J19: ='Consolidated BS'!L25-'Consolidated BS'!K25 -> 0 | K19: ='Consolidated BS'!M25-'Consolidated BS'!L25 -> 0 | L19: ='Consolidated BS'!N25-'Consolidated BS'!M25 -> 0 | ... W19: ='Consolidated BS'!Y25-'Consolidated BS'!X25 -> 0
D20: Proceeds from long-term debt | E20: ='Consolidated BS'!G21-'Consolidated BS'!F21 -> 0 | F20: ='Consolidated BS'!H21-'Consolidated BS'!G21 -> 0 | G20: ='Consolidated BS'!I21-'Consolidated BS'!H21 -> 0 | H20: ='Consolidated BS'!J21-'Consolidated BS'!I21 -> 0 | I20: ='Consolidated BS'!K21-'Consolidated BS'!J21 -> 0 | J20: ='Consolidated BS'!L21-'Consolidated BS'!K21 -> 0 | K20: ='Consolidated BS'!M21-'Consolidated BS'!L21 -> 0 | L20: ='Consolidated BS'!N21-'Consolidated BS'!M21 -> 0 | ... W20: ='Consolidated BS'!Y21-'Consolidated BS'!X21 -> 0
D21: Dividends paid | E21: =-Assumptions!F60 -> -25000 | F21: =-Assumptions!G60 -> -25000 | G21: =-Assumptions!H60 -> -25000 | H21: =-Assumptions!I60 -> -50000 | I21: =-Assumptions!J60 -> -50000 | J21: =-Assumptions!K60 -> -50000 | K21: =-Assumptions!L60 -> -50000 | L21: =-Assumptions!M60 -> -200000 | ... W21: =-Assumptions!X60 -> -380000
C22: Net Cash from Financing Activities | E22: =SUM(E18:E21) -> 1584.0423 | F22: =F18+F19+F20+F21 -> -104850.91 | G22: =G18+G19+G20+G21 -> 63833.327 | H22: =H18+H19+H20+H21 -> -144166.1 | I22: =I18+I19+I20+I21 -> 111550.41 | J22: =J18+J19+J20+J21 -> -211550.41 | K22: =K18+K19+K20+K21 -> -50000 | L22: =L18+L19+L20+L21 -> -200000 | M22: =M18+M19+M20+M21 -> -120944.82 | ... W22: =W18+W19+W20+W21 -> -403526.17
C24: Net change in cash | E24: =E11+E15+E22 -> 26466.646 | F24: =F11+F15+F22 -> 8450.6671 | G24: =G11+G15+G22 -> 30899.425 | H24: =H11+H15+H22 -> 58910.085 | I24: =I11+I15+I22 -> -15050.972 | J24: =J11+J15+J22 -> 41024.872 | K24: =K11+K15+K22 -> 62093.883 | L24: =L11+L15+L22 -> 126916.27 | ... W24: =W11+W15+W22 -> 47179.642
D25: Beginning cash balance | E25: ='Consolidated BS'!F7+'Consolidated BS'!F6 -> 645409.21 | F25: ='Consolidated BS'!G7+'Consolidated BS'!G6 -> 671875.86 | G25: ='Consolidated BS'!H7+'Consolidated BS'!H6 -> 680326.53 | H25: ='Consolidated BS'!I7+'Consolidated BS'!I6 -> 711225.95 | I25: ='Consolidated BS'!J7+'Consolidated BS'!J6 -> 770136.04 | J25: ='Consolidated BS'!K7+'Consolidated BS'!K6 -> 755085.06 | K25: ='Consolidated BS'!L7+'Consolidated BS'!L6 -> 796109.94 | L25: ='Consolidated BS'!M7+'Consolidated BS'!M6 -> 858203.82 | ... W25: ='Consolidated BS'!X7+'Consolidated BS'!X6 -> 1091858.5
D26: Ending cash blanace | E26: =SUM(E24:E25) -> 671875.86 | F26: =SUM(F24:F25) -> 680326.53 | G26: =SUM(G24:G25) -> 711225.95 | H26: =SUM(H24:H25) -> 770136.04 | I26: =SUM(I24:I25) -> 755085.06 | J26: =SUM(J24:J25) -> 796109.94 | K26: =SUM(K24:K25) -> 858203.82 | L26: =SUM(L24:L25) -> 985120.09 | ... W26: =SUM(W24:W25) -> 1139038.1

Sheet DCF Growth
A1: Discounted Cash Flows
C3: Proj. | D3: Proj. | E3: Proj. | F3: Proj. | G3: Proj. | H3: Proj. | I3: Proj. | J3: Proj. | K3: Proj. | L3: Proj. | M3: Proj. | N3: Proj. | O3: Proj. | P3: Proj. | Q3: Proj. | R3: Proj. | S3: Proj. | T3: Proj. | U3: Proj. | W3: Annual Projections
B4: Consolidated | C4: ='Consolidated SCF'!E3 -> Q2 2018 | D4: ='Consolidated SCF'!F3 -> Q3 2018 | E4: ='Consolidated SCF'!G3 -> Q4 2018 | F4: ='Consolidated SCF'!H3 -> Q1 2019 | G4: ='Consolidated SCF'!I3 -> Q2 2019 | H4: ='Consolidated SCF'!J3 -> Q3 2019 | I4: ='Consolidated SCF'!K3 -> Q4 2019 | J4: ='Consolidated SCF'!L3 -> Q1 2020 | ... U4: ='Consolidated SCF'!W3 -> Q4 2022 | W4: 2018 | X4: 2019 | Y4: 2020 | Z4: 2021 | AA4: 2022 | AC4: Steady State
B5: EBIT(1-t) | C5: =('Consolidated P&L'!H$6+'Consolidated P&L'!H$11)*(1-Assumptions!F$62) -> 229659.67 | D5: =('Consolidated P&L'!I$6+'Consolidated P&L'!I$11)*(1-Assumptions!G$62) -> 200446.24 | E5: =('Consolidated P&L'!J$6+'Consolidated P&L'!J$11)*(1-Assumptions!H$62) -> 291487.2 | F5: =('Consolidated P&L'!K$6+'Consolidated P&L'!K$11)*(1-Assumptions!I$62) -> 297338.3 | G5: =('Consolidated P&L'!L$6+'Consolidated P&L'!L$11)*(1-Assumptions!J$62) -> 391482.36 | H5: =('Consolidated P&L'!M$6+'Consolidated P&L'!M$11)*(1-Assumptions!K$62) -> 355758.62 | I5: =('Consolidated P&L'!N$6+'Consolidated P&L'!N$11)*(1-Assumptions!L$62) -> 463208.15 | J5: =('Consolidated P&L'!O$6+'Consolidated P&L'!O$11)*(1-Assumptions!M$62) -> 431114.92 | ... U5: =('Consolidated P&L'!Z$6+'Consolidated P&L'!Z$11)*(1-Assumptions!X$62) -> 840918.93 | W5: =SUM($C5:$E5) -> 721593.1 | X5: =SUM($F5:$I5) -> 1507787.4 | Y5: =SUM($J5:$M5) -> 2069686.6 | Z5: =SUM($N5:$Q5) -> 2552201.2 | AA5: =SUM($R5:$U5) -> 3019335.3 | AC5: =$AA5*(1+C13) -> 3143128
B6: +Depr | C6: =-('Consolidated P&L'!H$10) -> 147872.21 | D6: =-('Consolidated P&L'!I$10) -> 149304.35 | E6: =-('Consolidated P&L'!J$10) -> 150766.89 | F6: =-('Consolidated P&L'!K$10) -> 155966.88 | G6: =-('Consolidated P&L'!L$10) -> 157560.82 | H6: =-('Consolidated P&L'!M$10) -> 164217.43 | I6: =-('Consolidated P&L'!N$10) -> 166080.95 | J6: =-('Consolidated P&L'!O$10) -> 171655.94 | ... U6: =-('Consolidated P&L'!Z$10) -> 222342.91 | W6: =SUM($C6:$E6) -> 447943.45 | X6: =SUM($F6:$I6) -> 643826.08 | Y6: =SUM($J6:$M6) -> 708884.9 | Z6: =SUM($N6:$Q6) -> 775743.83 | AA6: =SUM($R6:$U6) -> 855572 | AC6: =-('Consolidated BS'!Y12*C13) -> -492296.11
B7: -Capex | C7: ='Consolidated SCF'!E$14 -> -225880.64 | D7: ='Consolidated SCF'!F14 -> -227000.79 | E7: ='Consolidated SCF'!G$14 -> -337175.44 | F7: ='Consolidated SCF'!H$14 -> -242648.64 | G7: ='Consolidated SCF'!I$14 -> -547131.73 | H7: ='Consolidated SCF'!J$14 -> -263897.89 | I7: ='Consolidated SCF'!K$14 -> -373107.33 | J7: ='Consolidated SCF'!L$14 -> -281079.72 | K7: ='Consolidated SCF'!M$14 -> -583017.96 | L7: ='Consolidated SCF'!N$14 -> -298276.12 | ... U7: ='Consolidated SCF'!W$14 -> -430851.19 | W7: =SUM($C7:$E7) -> -790056.88 | X7: =SUM($F7:$I7) -> -1426785.6 | Y7: =SUM($J7:$M7) -> -1514705.9 | Z7: =SUM($N7:$Q7) -> -1770908.9 | AA7: =SUM($R7:$U7) -> -2013404.8
B8: -ΔNOWC | C8: =-('Consolidated BS'!G31-'Consolidated BS'!F31) -> -116487.65 | D8: =-('Consolidated BS'!H31-'Consolidated BS'!G31) -> 19131.203 | E8: =-('Consolidated BS'!I31-'Consolidated BS'!H31) -> -132730.32 | F8: =-('Consolidated BS'!J31-'Consolidated BS'!I31) -> 18170.618 | G8: =-('Consolidated BS'!K31-'Consolidated BS'!J31) -> -124872.41 | H8: =-('Consolidated BS'!L31-'Consolidated BS'!K31) -> 23232.819 | I8: =-('Consolidated BS'!M31-'Consolidated BS'!L31) -> -145004.85 | J8: =-('Consolidated BS'!N31-'Consolidated BS'!M31) -> 30624.186 | ... U8: =-('Consolidated BS'!Y31-'Consolidated BS'!X31) -> -161793.74 | W8: =SUM($C8:$E8) -> -230086.76 | X8: =SUM($F8:$I8) -> -228473.82 | Y8: =SUM($J8:$M8) -> -237516.64 | Z8: =SUM($N8:$Q8) -> -237366.36 | AA8: =SUM($R8:$U8) -> -222724.22 | AC8: =-('Consolidated BS'!Y31*C13) -> -91338.91
B9: Free Cash Flow | C9: =SUM(C$5:C$8) -> 35163.579 | D9: =SUM(D$5:D$8) -> 141880.99 | E9: =SUM(E$5:E$8) -> -27651.666 | F9: =SUM(F$5:F$8) -> 228827.16 | G9: =SUM(G$5:G$8) -> -122960.96 | H9: =SUM(H$5:H$8) -> 279310.98 | I9: =SUM(I$5:I$8) -> 111176.92 | J9: =SUM(J$5:J$8) -> 352315.33 | ... U9: =SUM(U$5:U$8) -> 470616.91 | W9: =SUM($C9:$E9) -> 149392.9 | X9: =SUM($F9:$I9) -> 496354.1 | Y9: =SUM($J9:$M9) -> 1026349 | Z9: =SUM($N9:$Q9) -> 1319669.9 | AA9: =SUM($R9:$U9) -> 1638778.2 | AC9: =SUM(AC5:AC8) -> 2559493
B10: PV | C10: =C$9/(1+$C$14)^C$11 -> 34341.911 | D10: =D$9/(1+$C$14)^D$11 -> 135327.79 | E10: =E$9/(1+$C$14)^E$11 -> -25758.197 | F10: =F$9/(1+$C$14)^F$11 -> 208177.17 | G10: =G$9/(1+$C$14)^G$11 -> -109250.68 | H10: =H$9/(1+$C$14)^H$11 -> 242368.57 | I10: =I$9/(1+$C$14)^I$11 -> 94218.093 | J10: =J$9/(1+$C$14)^J$11 -> 291596.7 | ... U10: =U$9/(1+$C$14)^U$11 -> 300305.85 | AA10: Terminal Value | AC10: =(AC9/(C14-C13))*(1+C14)^0.5 -> 46111656
C11: 0.25 | D11: 0.5 | E11: 0.75 | F11: 1 | G11: 1.25 | H11: 1.5 | I11: 1.75 | J11: 2 | K11: 2.25 | L11: 2.5 | M11: 2.75 | N11: 3 | O11: 3.25 | P11: 3.5 | Q11: 3.75 | R11: 4 | S11: 4.25 | T11: 4.5 | U11: 4.75
B13: Terminal Growth Rate | C13: 0.041 | E13: D/V | F13: =1-F14 -> 0.11111111 | G13: D/E | H13: =COMPS!I23 -> 0.125 | I13: Rf | J13: =COMPS!I19 -> 0.0302 | W13: PVpp | X13: =SUM(C10:U10) -> 3436736.5
B14: WACC | C14: =F14*F16+F13*F15*(1-Assumptions!J62) -> 0.099194302 | E14: E/V | F14: =1/(1+H13) -> 0.88888889 | I14: MRP | J14: =COMPS!I20 -> 0.0596 | W14: PVtv | X14: =AC10/(1+C14)^4.75 -> 29424358
E15: Cost of Debt | F15: 0.0625
E16: Cost of Equity | F16: =J13+S31*J14 -> 0.10628109 | W16: Enterprise Value | X16: =SUM(X13:X14) -> 32861094
E21: Manufacturing | F21: Share Price | G21: # Share Outstanding | H21: Book Value Debt | I21: TTM EBITDA | J21: Observed Beta | K21: Tax Rate | M21: Manufacturing | O21: Unlevered Beta | S21: Averages
E22: Business A | F22: 17.46 | G22: 8113783 | H22: 17000000 | I22: 32043263 | J22: 1.622 | K22: 0.375 | M22: "mature & moderate growth" | O22: =$J22/((1+(1-$K22)*($H22/($F22*$G22)))) -> 1.5088372 | Q22: Manufacturing | R22: Young & Quick | S22: =AVERAGE(O25,O27, O28) -> 1.4997233
E23: Business B | F23: 53.91 | G23: 1138260 | H23: 13500000 | I23: 12645489 | J23: 1.551 | K23: 0.34 | M23: "mature & moderate growth" | O23: =$J23/((1+(1-$K23)*($H23/($F23*$G23)))) -> 1.3543485 | Q23: Manufacturing | R23: Mature and Moderate | S23: =AVERAGE(O22:O24, O26) -> 1.2925922
E24: Business C | F24: 11.26 | G24: 9069952 | H24: 48000000 | I24: 39847189 | J24: 1.532 | K24: 0.38 | M24: "mature & moderate growth" | O24: =$J24/((1+(1-$K24)*($H24/($F24*$G24)))) -> 1.1863094 | Q24: Manufacturing | R24: Total | S24: =AVERAGE(O22:O28) -> 1.3813627
E25: Business D | F25: 27.01 | G25: 629396 | H25: 3400000 | I25: 1080564 | J25: 1.667 | K25: 0.365 | M25: "younger & quicker growth" | O25: =$J25/((1+(1-$K25)*($H25/($F25*$G25)))) -> 1.479148 | Q25: Service | R25: Young & Quick | S25: =O32 -> 1.0897889
E26: Business E | F26: 104.98 | G26: 1734457 | H26: 65550000 | I26: 45164743 | J26: 1.365 | K26: 0.395 | M26: "mature & moderate growth" | O26: =$J26/((1+(1-$K26)*($H26/($F26*$G26)))) -> 1.1208737 | Q26: Service | R26: Mature & Moderate | S26: =O31 -> 0.99014031
E27: Business F | F27: 19.44 | G27: 1876523 | H27: 9484700 | I27: 2969480 | J27: 1.745 | K27: 0.362 | M27: "younger & quicker growth" | O27: =$J27/((1+(1-$K27)*($H27/($F27*$G27)))) -> 1.4967235 | Q27: Service | R27: Total | S27: =AVERAGE(O31:O32) -> 1.0399646
E28: Business G | F28: 29.55 | G28: 1687576 | H28: 4488110 | I28: 3300726 | J28: 1.612 | K28: 0.353 | M28: "younger & quicker growth" | O28: =$J28/((1+(1-$K28)*($H28/($F28*$G28)))) -> 1.5232983
E30: Service | M30: Service | R30: Firm Unlevered | S30: =0.4*S24+0.6*S27 -> 1.1765238
E31: Business H | F31: 37.54 | G31: 1116379 | H31: 13410843 | I31: 4837001 | J31: 1.185 | K31: 0.385 | M31: "mature & moderate growth" | O31: =$J31/((1+(1-$K31)*($H31/($F31*$G31)))) -> 0.99014031 | R31: Re-levered | S31: =S30*(1+(H13)*(1-Assumptions!J62)) -> 1.2765284
E32: Business I | F32: 12.12 | G32: 1943312 | H32: 2826353 | I32: 929967 | J32: 1.171 | K32: 0.379 | M32: "younger & quicker growth" | O32: =$J32/((1+(1-$K32)*($H32/($F32*$G32)))) -> 1.0897889
M34: Total | O34: =AVERAGE(O22:O28, O31:O32) -> 1.3054964
C37: DATA TABLE
C38: =$X$16 -> 32861094 | D38: =E38-0.002 -> 0.037 | E38: =F38-0.002 -> 0.039 | F38: 0.041 | G38: =F38+0.002 -> 0.043 | H38: =G38+0.002 -> 0.045
C39: =C40-0.001 -> 0.097194302 | D39: 0.097194302 | E39: 0.097194302 | F39: 0.097194302 | G39: 0.097194302 | H39: 0.097194302
C40: =C41-0.001 -> 0.098194302 | D40: 0.098194302 | E40: 0.098194302 | F40: 0.098194302 | G40: 0.098194302 | H40: 0.098194302
C41: 0.099194302 | D41: 0.099194302 | E41: 0.099194302 | F41: 0.099194302 | G41: 0.099194302 | H41: 0.099194302
C42: =C41+0.001 -> 0.1001943 | D42: 0.1001943 | E42: 0.1001943 | F42: 0.1001943 | G42: 0.1001943 | H42: 0.1001943
C43: =C42+0.001 -> 0.1011943 | D43: 0.1011943 | E43: 0.1011943 | F43: 0.1011943 | G43: 0.1011943 | H43: 0.1011943

Sheet DCF Multiple
A1: Discounted Cash Flows
C3: Proj. | D3: Proj. | E3: Proj. | F3: Proj. | G3: Proj. | H3: Proj. | I3: Proj. | J3: Proj. | K3: Proj. | L3: Proj. | M3: Proj. | N3: Proj. | O3: Proj. | P3: Proj. | Q3: Proj. | R3: Proj. | S3: Proj. | T3: Proj. | U3: Proj. | W3: Annual Projections
B4: Consolidated | C4: ='Consolidated SCF'!E3 -> Q2 2018 | D4: ='Consolidated SCF'!F3 -> Q3 2018 | E4: ='Consolidated SCF'!G3 -> Q4 2018 | F4: ='Consolidated SCF'!H3 -> Q1 2019 | G4: ='Consolidated SCF'!I3 -> Q2 2019 | H4: ='Consolidated SCF'!J3 -> Q3 2019 | I4: ='Consolidated SCF'!K3 -> Q4 2019 | J4: ='Consolidated SCF'!L3 -> Q1 2020 | ... U4: ='Consolidated SCF'!W3 -> Q4 2022 | W4: 2018 | X4: 2019 | Y4: 2020 | Z4: 2021 | AA4: 2022
B5: EBIT(1-t) | C5: ='DCF Growth'!C5 -> 229659.67 | D5: ='DCF Growth'!D5 -> 200446.24 | E5: ='DCF Growth'!E5 -> 291487.2 | F5: ='DCF Growth'!F5 -> 297338.3 | G5: ='DCF Growth'!G5 -> 391482.36 | H5: ='DCF Growth'!H5 -> 355758.62 | I5: ='DCF Growth'!I5 -> 463208.15 | J5: ='DCF Growth'!J5 -> 431114.92 | ... U5: ='DCF Growth'!U5 -> 840918.93 | W5: =SUM(C5:E5) -> 721593.1 | X5: =SUM(F5:I5) -> 1507787.4 | Y5: =SUM(J5:M5) -> 2069686.6 | Z5: =SUM(N5:Q5) -> 2552201.2 | AA5: =SUM(R5:U5) -> 3019335.3
